<!-- 需求：设置机器人底盘，并添加摄像头 -->
<!-- 
    需求: 创建机器人模型，底盘为长方体，
         在长方体的前面添加一摄像头，
         摄像头可以沿着 Z 轴 360 度旋转

 -->
<robot name="mycar">

    <link name="base_footprint">
        <visual>
            <geometry>
                <box size="0.001 0.001 0.001" />
            </geometry>
        </visual>
    </link>
    <!-- 添加一个尺寸极小的link,再去关联初始link与base_link，关节的高度刚好和base_link下沉的高度一致(半个底盘高度) -->
    <!-- 底盘 -->
    <link name="base_link">
        <visual>
            <geometry>
                <box size="0.3 0.2 0.1" />
            </geometry>
            <origin xyz="0 0 0" rpy="0 0 0" />
            <material name="car_color">
                <color rgba="0 0 1.0 0.5" />
            </material>
        </visual>
    </link>
    
    
    <!-- 摄像头 -->
    <link name="camera">
        <visual>
            <geometry>
                <box size="0.02 0.05 0.05" />
            </geometry>
            <origin xyz="0 0 0.001" rpy="0 0 0" />
            <material name="red">
                <color rgba="1 0 0 0.5" />
            </material>
        </visual>
    </link>

    <!-- 关节 -->

    <!-- 关联base_footprint与base_link -->
    <joint name="link2footprint" type="fixed">
        <parent link="base_footprint"/>
        <child link="base_link" />
        <!-- 需要计算两个 link 的物理中心之间的偏移量 -->
        <origin xyz="0 0 0.05" rpy="0 0 0" />
        <axis xyz="0 0 1" />
    </joint>


    <joint name="camera2baselink" type="continuous">
        <parent link="base_link"/>
        <child link="camera" />
        <!-- 需要计算两个 link 的物理中心之间的偏移量 -->
        <origin xyz="0.2 0 0.075" rpy="0 0 0" />
        <axis xyz="0 0 1" />
    </joint>

</robot>
